Traceback (most recent call last):
  File "/opt/hostedtoolcache/Python/3.11.13/x64/lib/python3.11/site-packages/jupyter_core/utils/__init__.py", line 154, in wrapped
    asyncio.get_running_loop()
RuntimeError: no running event loop

During handling of the above exception, another exception occurred:

Traceback (most recent call last):
  File "/opt/hostedtoolcache/Python/3.11.13/x64/lib/python3.11/site-packages/jupyter_cache/executors/utils.py", line 58, in single_nb_execution
    executenb(
  File "/opt/hostedtoolcache/Python/3.11.13/x64/lib/python3.11/site-packages/nbclient/client.py", line 1319, in execute
    return NotebookClient(nb=nb, resources=resources, km=km, **kwargs).execute()
           ^^^^^^^^^^^^^^^^^^^^^^^^^^^^^^^^^^^^^^^^^^^^^^^^^^^^^^^^^^^^^^^^^^^^^
  File "/opt/hostedtoolcache/Python/3.11.13/x64/lib/python3.11/site-packages/jupyter_core/utils/__init__.py", line 158, in wrapped
    return loop.run_until_complete(inner)
           ^^^^^^^^^^^^^^^^^^^^^^^^^^^^^^
  File "/opt/hostedtoolcache/Python/3.11.13/x64/lib/python3.11/asyncio/base_events.py", line 654, in run_until_complete
    return future.result()
           ^^^^^^^^^^^^^^^
  File "/opt/hostedtoolcache/Python/3.11.13/x64/lib/python3.11/site-packages/nbclient/client.py", line 709, in async_execute
    await self.async_execute_cell(
  File "/opt/hostedtoolcache/Python/3.11.13/x64/lib/python3.11/site-packages/nbclient/client.py", line 1062, in async_execute_cell
    await self._check_raise_for_error(cell, cell_index, exec_reply)
  File "/opt/hostedtoolcache/Python/3.11.13/x64/lib/python3.11/site-packages/nbclient/client.py", line 918, in _check_raise_for_error
    raise CellExecutionError.from_cell_and_msg(cell, exec_reply_content)
nbclient.exceptions.CellExecutionError: An error occurred while executing the following cell:
------------------
samples = np.array(smc_samples.particles[:, 0])
_ = plt.hist(samples, bins=100, density=True)
_ = plt.plot(linspace.squeeze(), density[-1])
------------------


[31m---------------------------------------------------------------------------[39m
[31mNameError[39m                                 Traceback (most recent call last)
[36mCell[39m[36m [39m[32mIn[13][39m[32m, line 1[39m
[32m----> [39m[32m1[39m samples = np.array([43msmc_samples[49m.particles[:, [32m0[39m])
[32m      2[39m _ = plt.hist(samples, bins=[32m100[39m, density=[38;5;28;01mTrue[39;00m)
[32m      3[39m _ = plt.plot(linspace.squeeze(), density[-[32m1[39m])

[31mNameError[39m: name 'smc_samples' is not defined

